Workbook

Sheet TRANG_CHU
B2: BỘ CÔNG CỤ LẬP BÁO CÁO TÀI CHÍNH PHỤC VỤ HỢP NHẤT (CHUẨN KẾ TOÁN TỔ CHỨC TÍN DỤNG - TCTD)
B5: 📁 BƯỚC 1: CHỌN FILE BẢNG CÂN ĐỐI TÀI KHOẢN (TT200)
B6: 1.1. Bấm nút macro: | C6: 👉 [ BẤM ĐỂ CHỌN FILE CĐTK ] (Macro: ChonFileBangCanDoi)
B7: 1.2. Đường dẫn file: | C7: data/Bang_can_doi_tai_khoanQ22026.xlsx
B8: 1.3. Kỳ kế toán nhận diện: | C8: QUÝ 2 NĂM 2026
B10: ⚙️ BƯỚC 2: CẤU HÌNH BÚT TOÁN CẤN TRỪ (Intercompany Elimination)
B12: STT | C12: Tên bút toán cấn trừ / điều chỉnh | D12: Tự động gợi ý (VND) | E12: Sửa thủ công (nếu có) | F12: Ghi chú
B13: 1 | C13: Cấn trừ trung gian ngoại tệ (TK 33886.02 / 13885.02) | D13: 10460694846 | F13: Tự lấy số dư CK TK 13885.02
B14: 2 | C14: Chuyển phải thu NHCT về tiền gửi (TK 11211.01 / 13881) | D14: 18358019545 | F14: Tự lấy số dư CK TK 13881
B15: 3 | C15: Cấn trừ đối tác Western Union (WU) (TK 33882.01 / 13882.02) | D15: 0 | F15: Mặc định 0
B16: 4 | C16: Cấn trừ các tài khoản WASH (TK 33883.01 / 1121) | D16: 0 | F16: Mặc định 0
B18: ⚡ BƯỚC 3: CẬP NHẬT SỐ LIỆU & LẬP BÁO CÁO HỢP NHẤT | C18: 👉 [ BẤM ĐỂ LẬP BÁO CÁO HỢP NHẤT ] (Macro: CapNhatVaLapBaoCaoHopNhat)
B20: 📊 KẾT QUẢ KIỂM TRA TÍNH CÂN ĐỐI (STATUS DASHBOARD)
B21: Chỉ tiêu đối chiếu | C21: Tổng Nợ (VNĐ) | D21: Tổng Có (VNĐ) | E21: Trạng thái cân đối | F21: Đánh giá
B22: 1. Số dư Đầu kỳ (Sheet so lieu) | C22: 231464686791 | D22: 231464686791 | E22: CÂN ĐỐI (0 đ) | F22: ✅ Hoàn hảo
B23: 2. Phát sinh trong kỳ (Sheet so lieu) | C23: 52142209214992 | D23: 52142209214992 | E23: CÂN ĐỐI (0 đ) | F23: ✅ Hoàn hảo
B24: 3. Số dư Cuối kỳ (Sheet so lieu) | C24: 315725226474 | D24: 315725226474 | E24: CÂN ĐỐI (0 đ) | F24: ✅ Hoàn hảo

Sheet B02
A1: ĐƠN VỊ BÁO CÁO: Ten cong ty
A2: Địa chỉ : Dia chi | D2: Mẫu số : B02a/TCTD: BCTC riêng lẻ
A4: BÁO CÁO TÌNH HÌNH TÀI CHÍNH GIỮA NIÊN ĐỘ
A5: (Dạng đầy đủ)
A6: Quý I năm 2026
A8: STT | B8: Chỉ tiêu | C8: Thuyết minh | D8: Số cuối quý | E8: Số đầu năm
B9: -1 | C9: -2 | D9: -3 | E9: -4 | F9: -5 | G9: -6
A10: A | B10: TÀI SẢN
A11: I | B11: Tiền mặt, vàng bạc, đá quý | D11: ='so lieu'!F1 | E11: 310486901 | F11: DN: TK 101, 103, 104, 105 | G11: Tổng các khoản mục tương ứng trên BCTC Riêng lẻ và BCTC của Công ty trực thuộc
A12: II | B12: Tiền gửi tại NHNN | F12: DN: TK 111, 112 | G12: Như trên
A13: III | B13: Tiền, vàng gửi tại các TCTD khác và cho vay các TCTD khác | D13: =D14+D15+D16 | E13: 570172258783 | G13: Như trên | H13: =D13-E13
A14: 1 | B14: Tiền, vàng gửi tại các TCTD khác | D14: ='so lieu'!F2+'so lieu'!F3+'so lieu'!F4 | E14: 570172258783 | F14: DN TK 131,132, 133, 134, 135, 136 | G14: Như trên | J14: 13161293262 | K14: 12477370150
A15: 2 | B15: Cho vay các TCTD khác | F15: DN TK 201, 202, 203, 205. | G15: Như trên
A16: 3 | B16: Dự phòng rủi ro cho vay các TCTD khác (*) | F16: DC: TK 209 | G16: Như trên
A17: IV | B17: Chứng khoán kinh doanh | G17: Như trên
A18: 1 | B18: Chứng khoán kinh doanh (1) | F18: Chênh lệch (DN - DC) TK: 141, 142, 148 | G18: Như trên
A19: 2 | B19: Dự phòng giảm giá chứng khoán kinh doanh (*) | F19: DC TK: 149 | G19: Như trên
A20: V | B20: Các công cụ tài chính phái sinh và các tài sản tài chính khác | F20: Chênh lệch DN TK: 486 (nếu DN > DC) | G20: Như trên
A21: VI | B21: Cho vay khách hàng | G21: Như trên
A22: 1 | B22: Cho vay khách hàng | F22: DN TK 211, 212, 213, 214, 215, 216, 221, 222, 231, 232, 241, 242, 251, 252, 253, 254, 255, 256, 261, 262, 263, 264, 265, 266, 267, 268, 271, 272, 273, 275, 281, 282, 283, 284, 285, 291, 292, 293. | G22: Như trên
A24: 2 | B24: Dự phòng rủi ro cho vay khách hàng (*) | F24: DC TK 219, 229, 239, 249, 259, 269, 279, 289, 299. | G24: Như trên
A25: VII | B25: Hoạt động mua nợ | C25: V.07
A26: 1 | B26: Mua nợ | F26: DN TK 371, 372 | G26: Như trên
A27: 2 | B27: Dự phòng rủi ro hoạt động mua nợ (*) | F27: DC TK 379 | G27: Như trên
A28: VIII | B28: Chứng khoán đầu tư | G28: Như trên
A29: 1 | B29: Chứng khoán đầu tư sẵn sàng để bán (2) | F29: DN TK 121, 122, 123 | G29: Như trên
F30: Chênh lệch (DN - DC) TK 151, 152, 153, 154, 155, 156, 157.
A31: 2 | B31: Chứng khoán đầu tư giữ đến ngày đáo hạn | F31: Chênh lệch (DN - DC) TK 161, 162, 163, 164. | G31: Như trên
A32: 3 | B32: Dự phòng giảm giá chứng khoán đầu tư (*) | F32: DC TK: 129, 159, 169. | G32: Như trên
A33: XI | B33: Góp vốn, đầu tư dài hạn | G33: Như trên
A34: 1 | B34: Đầu tư vào công ty trực thuộc | F34: DN TK: 341, 345 | G34: Không thể hiện trên Bảng CĐKT hợp nhất
A35: 2 | B35: Vốn góp liên doanh | F35: DN TK: 342, 346 | G35: Lấy số liệu từ hệ thống sổ kế toán phục vụ cho hợp nhất
A36: 3 | B36: Đầu tư vào công ty liên kết | F36: DN TK: 343, 347
A37: 4 | B37: Đầu tư dài hạn khác | F37: DN TK: 344, 348 | G37: Tổng các khoản mục tương ứng trên BCTC riêng lẻ và BCTC Công ty trực thuộc
A38: 5 | B38: Dự phòng giảm giá đầu tư dài hạn (*) | F38: DC TK: 349 | G38: như trên
A39: X | B39: Tài sản cố định | D39: =D40+D43+D46 | E39: 40695988 | F39: (1+2+3)
A40: 1 | B40: Tài sản cố định hữu hình | D40: =D41+D42 | E40: 40695988 | F40: (a + b)
A41: a | B41: Nguyên giá TSCĐ | D41: ='so lieu'!F6+'so lieu'!F5+'so lieu'!F8+'so lieu'!F7 | E41: 2778069546 | F41: DN TK: 301 | G41: như trên
A42: b | B42: Hao mòn TSCĐ (*) | D42: =-'so lieu'!G10-'so lieu'!G9 | E42: -2737373558 | F42: DC TK: 3051 | G42: như trên
A43: 2 | B43: Tài sản cố định thuê tài chính | F43: (a + b)
...

Sheet B03
A1: ĐƠN VỊ BÁO CÁO: Ten cong ty | L1: Mẫu số : B03a/TCTD
A2: Địa chỉ : Dia chi
A4: BÁO CÁO KẾT QUẢ HOẠT ĐỘNG
A5: (Dạng đầy đủ)
A7: Năm 2026
A8: Ngày 31/03/2026
A11: TT | B11: Chỉ tiêu | C11: TM | D11: Quý I | F11: Quý III | H11: Quý II | J11: Quý I | L11: Luỹ kế từ đầu năm đến cuối quý này | N11: Cách lấy số liệu từ BCĐTKKT (áp dụng cho Báo cáo KQHĐKD | O11: Cách lấy số liệu đối với Báo cáo KQHĐKD hợp nhất
D12: Năm nay | E12: Năm trước | F12: 2021 | G12: 2020 | H12: 2021 | I12: 2020 | J12: 2021 | K12: 2020 | L12: Năm nay | M12: Năm trước
B13: -1 | C13: -2 | D13: -3 | E13: -4 | F13: -3 | G13: -4 | H13: -3 | I13: -4 | J13: -3 | K13: -4 | L13: -3 | M13: -4 | N13: -7 | O13: -8
A14: 1 | B14: Thu nhập lãi và các khoản thu nhập tương tự | D14: ='so lieu'!E42-'so lieu'!D42 | E14: 762740128 | L14: =F14+H14+J14+D14 | M14: =G14+I14+K14+E14 | N14: TK 701, 702, 7030.01,705, 709. | O14: Tổng các khoản mục tương ứng trên BCTC Riêng lẻ và BCTC của Công ty trực thuộc | Q14: 2850907902 | R14: =L14-Q14
A15: 2 | B15: Chi phí lãi và các chi phí tương tự | L15: =F15+H15+J15+D15 | M15: =G15+I15+K15+E15 | N15: TK 801, 802, 803, 805, 809 | O15: như trên | Q15: 0 | R15: =L15-Q15
A16: I | B16: Thu nhập lãi thuần | C16: VI 1 | D16: =D14-D15 | E16: 762740128 | L16: =L14-L15 | M16: =G16+I16+K16+E16 | N16: (1 – 2) | Q16: 2850907902 | R16: =L16-Q16
A17: 3 | B17: Thu nhập từ hoạt động dịch vụ | D17: ='so lieu'!E43 | E17: 11184553194 | L17: =F17+H17+J17+D17 | M17: =G17+I17+K17+E17 | N17: DC TK: 71 | O17: như trên | Q17: 24340016593 | R17: =L17-Q17 | T17: =L14+L20
A18: 4 | B18: Chi phí hoạt động dịch vụ | D18: ='so lieu'!D47-'so lieu'!E47 | E18: 2034499321 | L18: =F18+H18+J18+D18 | M18: =G18+I18+K18+E18 | N18: DN TK: 81 | O18: như trên | Q18: 13013617811 | R18: =L18-Q18
A19: II | B19: Lãi/lỗ thuần từ hoạt động dịch vụ | D19: =D17-D18 | E19: 9150053873 | L19: =F19+H19+J19+D19 | M19: =G19+I19+K19+E19 | N19: (3 – 4) | Q19: 11326398782 | R19: =L19-Q19
A20: III | B20: Lãi/lỗ thuần từ hoạt động kinh doanh ngoại hối | D20: ='so lieu'!E44-'so lieu'!D44-'so lieu'!D48 | E20: 456710901 | L20: =F20+H20+J20+D20 | M20: =G20+I20+K20+E20 | N20: DC TK 72 - DN TK 82 (nếu kết quả âm thì ghi âm (-) | O20: như trên | Q20: 194437976 | R20: =L20-Q20
A21: IV | B21: Lãi/lỗ thuần từ mua bán chứng khoán kinh doanh | L21: =F21+H21+J21+D21 | M21: =G21+I21+K21+E21 | N21: Ch lệch thu chi giữa số dư TK 741 và TK 841 (phần của chứng khoán kinh doanh) trừ đi (-) DNTK 8823.01(Nếu kết quả âm thì ghi (-) | O21: như trên | R21: =L21-Q21
A22: V | B22: Lãi/lỗ thuần từ mua bán chứng khoán đầu tư | L22: =F22+H22+J22+D22 | M22: =G22+I22+K22+E22 | N22: Chênh lệch thu chi giữa số dư TK 741, 841 (phần của CK đầu tư sẵn sàng để bán và CK đầu tư giữ đến ngày đáo hạn) trừ (Nếu kết quả âm thì ghi (-)đi (-) DN TK (8823.02 + 8823.03) | O22: như trên | R22: =L22-Q22
A23: 5 | B23: Thu nhập từ hoạt động khác | D23: ='so lieu'!E45+'so lieu'!E46-'so lieu'!D46 | E23: 0 | L23: =F23+H23+J23+D23 | M23: =G23+I23+K23+E23 | N23: TK 742, 748, 749, 79 (không bao gồm phần hoàn nhập dự phòng giảm giá chứng khoán hạch toán vào thu nhập khác) | O23: như trên | Q23: 3500000 | R23: =L23-Q23
A24: 6 | B24: Chi phí hoạt động khác | D24: ='so lieu'!D84-'so lieu'!E84+'so lieu'!D52-'so lieu'!E52 | E24: 105250 | L24: =F24+H24+J24+D24 | M24: =G24+I24+K24+E24 | N24: DN TK 842, 848, 849, 89 | O24: như trên | Q24: 69492 | R24: =L24-Q24
A25: VI | B25: Lãi/lỗ thuần từ hoạt động khác | D25: =D23-D24 | E25: -105250 | L25: =F25+H25+J25+D25 | M25: =G25+I25+K25+E25 | N25: (5 – 6) | Q25: 3430508 | R25: =L25-Q25
A26: VII | B26: Thu nhập từ góp vốn mua cổ phần | L26: =F26+H26+J26+D26 | M26: =G26+I26+K26+E26 | N26: DC TK 7030.02, 704, 78 | O26: như trên | R26: =L26-Q26
A27: VIII | B27: Chi phí hoạt động | C27: VI 2 | D27: ='so lieu'!H48 | E27: 5675453656 | L27: =F27+H27+J27+D27 | M27: =G27+I27+K27+E27 | N27: DN TK 831, 832, 85, 86, 87, 8821, 8824, 8825, 8826, 8827, (Dự phòng cam kết đưa ra không thuộc hoạt động tín dụng), 8829, 883 | O27: như trên
A28: IX | B28: Lợi nhuận thuần từ hoạt động kinh doanh trước chi phí dự phòng rủi ro tín dụng | D28: =D16+D19+D20+D21+D22+D25+D26-D27 | E28: 4693945996 | L28: =F28+H28+J28+D28 | M28: =G28+I28+K28+E28 | N28: (I + II + III + IV + V + VI + VII – VIII) | Q28: 8685258311 | R28: =L28-Q28
A29: X | B29: Chi phí dự phòng rủi ro tín dụng | L29: =F29+H29+J29+D29 | M29: =G29+I29+K29+E29 | N29: DN TK 8822 | O29: như trên | R29: =L29-Q29
A30: XI | B30: Tổng lợi nhuận trước thuế | D30: =D28 | E30: 4693945996 | L30: =F30+H30+J30+D30 | M30: =G30+I30+K30+E30 | N30: (IX-X) | Q30: 8685258311 | R30: =L30-Q30 | T30: chi phí
A31: 7 | B31: Chi phí thuế thu nhập hiện hành | D31: ='so lieu'!D51 | E31: 941810249 | L31: =F31+H31+J31+D31 | M31: =G31+I31+K31+E31 | N31: DN TK: 8331 | O31: như trên | Q31: 1931656829 | R31: =L31-Q31 | S31: =I31=[1]BCKQKD_B03!$F$31 | T31: Tăng | U31: 80000000
A32: 8 | B32: Chi phí thuế thu nhập hoãn lại | L32: =F32+H32+J32+D32 | M32: =G32+I32+K32+E32 | N32: DN TK: 8332 (Nếu DC ghi bằng số âm) | O32: như trên | R32: =L32-Q32 | U32: 19800000
A33: XII | B33: Chi phí thuế TNDN | D33: =D31 | E33: 941810249 | L33: =F33+H33+J33+D33 | M33: =G33+I33+K33+E33 | N33: (7 + 8) | Q33: 1931656829 | R33: =L33-Q33 | T33: Giảm | U33: 125400000
A34: XIII | B34: Lợi nhuận sau thuế | D34: =D30-D33 | E34: 3752135747 | L34: =F34+H34+J34+D34 | M34: =G34+I34+K34+E34 | N34: XI-XII | P34: =L34-'Thuế TNDN Q4'!D29 | Q34: 6753601482 | R34: =L34-Q34 | T34: Giảm | U34: =U33-U32-U31
A35: XIV | B35: Lợi ích của cổ đông thiểu số | L35: =F35+H35+J35+D35 | M35: =G35+I35+K35+E35 | O35: Lợi nhuận thuần của Công ty trực thuộc nhân (x) với tỷ lệ (%) vốn góp của các cổ đông thiểu số tại Công ty trực thuộc. | R35: =L35-Q35 | T35: =L30+U34
A36: XV | B36: Lợi nhuận thuần trong kỳ của chủ sở hữu | D36: =D34 | E36: 3752135747 | L36: =F36+H36+J36+D36 | M36: =G36+I36+K36+E36 | O36: XIII-XIV
A39: Lập bảng Kế toán trưởng Tổng giám đốc

Sheet B04
A1: ĐƠN VỊ BÁO CÁO: Ten cong ty | D1: Mẫu số: B04a/TCTD: BCTC riêng lẻ
A2: Địa chỉ : Dia chi
A4: BÁO CÁO LƯU CHUYỂN TIỀN TỆ GIỮA NIÊN ĐỘ
A5: (Theo phương pháp trực tiếp)
A6: (Dạng đầy đủ)
A7: Quý I năm 2026
C9: Đơn vị tính : Đồng Việt Nam (VNĐ)
A11: STT | B11: Chỉ tiêu | C11: TM | D11: Luỹ kế từ đầu năm đến cuối quý này | F11: Cách lấy số liệu Báo cáo LCTT riêng lẻ | G11: Cách lấy số liệu Báo cáo LCTT hợp nhất
D12: Năm nay | E12: Năm trước
A13: Lưu chuyển tiền tệ từ hoạt động kinh doanh
A14: 1 | B14: Thu nhập lãi và các khoản thu nhập tương tự nhận được | D14: =D15+D16-D17 | E14: 762740128 | F14: (a + b - c) | G14: (a +b –c) | M14: 3763468059 | N14: =D14-M14
A15: a | D15: ='so lieu'!B20 | F15: Dư Nợ đầu kỳ các TK: 391, 392, 394, 396 | G15: Tổng các khoản mục tương ứng trên BCTC Riêng lẻ và BCTC của Công ty trực thuộc
A16: b | D16: ='B03'!D14 | E16: 762740128 | F16: Điểm 1 mẫu B03 | G16: Như trên | M16: 3763468059 | N16: =D16-M16
A17: c | D17: ='so lieu'!F20 | F17: Dư Nợ cuối kỳ các TK: 391, 392 394, 396 | G17: Như trên
A18: 2 | B18: Chi phí lãi và các chi phí tương tự đã trả | D18: =D20 | E18: 0 | F18: (a + b – c) | M18: -2504311133 | N18: =D18-M18
A19: a | F19: Dư Có đầu kỳ các TK: 491, 492 493, 494, 496 | G19: Như trên
A20: b | D20: =-'B03'!L15 | E20: 0 | F20: Điểm 2 mẫu B03 | G20: Như trên | M20: 0
A21: c | F21: Dư Có cuối kỳ các TK 491, 492, 493, 494, 496 | G21: Như trên
A22: 3 | B22: Thu nhập từ hoạt động dịch vụ nhận được | D22: =D23+D24-D25-(D26+D27-D28) | E22: 10255790430 | F22: =F23+F24-F25-(F26+F27-F28) | G22: =G23+G24-G25-(G26+G27-G28) | H22: =H23+H24-H25-(H26+H27-H28) | I22: =I23+I24-I25-(I26+I27-I28) | J22: =J23+J24-J25-(J26+J27-J28) | K22: =K23+K24-K25-(K26+K27-K28) | L22: =L23+L24-L25-(L26+L27-L28) | M22: 14976648669 | N22: =D22-M22
A23: a | B23: Dư nợ đầu kỳ 397 | D23: ='so lieu'!B21 | E23: 4753543647 | F23: Dư Nợ đầu kỳ TK 397 | G23: như trên
A24: b | B24: Điểm 03 mẫu B03 | D24: ='B03'!L17 | E24: 11184553194 | F24: Điểm 3 mẫu B03 | G24: như trên | M24: 31450386776 | N24: =D24-M24
A25: c | B25: Dư nợ ck 397 | D25: ='so lieu'!F21 | E25: 3647807090 | F25: Dư Nợ cuối kỳ TK 397 | G25: như trên
A26: d | B26: DƯ có đầu kỳ 497 | D26: 0 | F26: Dư Có đầu kỳ TK 497 | G26: như trên | M26: 0
A27: e | B27: Điểm 04 mẫu B03 | D27: ='B03'!L18 | E27: 2034499321 | F27: Điểm 4 mẫu B03 | G27: như trên | M27: 16473738107 | N27: =D27-M27
A28: g | B28: Dư có ck 497 | D28: ='so lieu'!G35 | E28: 0 | F28: Dư Có cuối kỳ TK 497 | G28: như trên | M28: 0
A29: 4 | B29: Chênh lệch số tiền thực thu/ thực chi từ hoạt động kinh doanh (ngoại tệ, vàng bạc, chứng khoán) | D29: =D30+D31+D32 | E29: 456710901 | F29: (a + b + c) | M29: 267713904 | N29: =D29-M29
A30: a | B30: Điểm III b03 | D30: ='B03'!L20 | E30: 456710901 | F30: Mục III (Mẫu B03/TCTD) | G30: như trên | M30: 267713904 | N30: =D30-M30
A31: b | D31: ='B03'!F21 | E31: 0 | F31: Mục IV (Mẫu B03/TCTD): | G31: như trên
A32: c | D32: ='B03'!F22 | E32: 0 | F32: Mục V (Mẫu B03/TCTD): | G32: như trên
A33: 5 | B33: Thu nhập khác | D33: =D34-D35-D36-D37+D38 | E33: -105250 | F33: (a – b - c) | M33: 3413724
A34: a | D34: ='B03'!L23 | E34: 0 | F34: Điểm 5 (Mẫu B03/TCTD) | G34: như trên | M34: 3500000
A35: b | F35: Dư Có cuối kỳ TK 7900.05 | G35: như trên
A36: c | D36: ='B03'!L24 | E36: 105250 | F36: Điểm 6 (Mẫu B03/TCTD) | G36: như trên | M36: 86276
A37: d
A38: e
A39: 6 | B39: Tiền thu các khoản nợ đã được xử lý xoá, bù đắp bằng nguồn rủi ro | D39: 0 | E39: 0 | F39: Dư Có cuối kỳ TK 7900.05 | G39: như trên | M39: 0
A40: 7 | B40: Tiền chi trả cho nhân viên và hoạt động quản lý, công vụ (*) | D40: =-(D41+D42-D43-D44) | E40: -8031487537 | F40: (a + b - c) | K40: 85 + 86 + (DDC 4620 - DCC 4620) | M40: -8357331200
A41: a | B41: Dư có đầu kỳ TK 4620 | D41: ='so lieu'!C31 | E41: 4136351151 | F41: Dư Có đầu kỳ TK 4620 | G41: như trên | M41: 1081625666
A42: b | B42: Mục VIII mẫu B03 | D42: ='B03'!L27 | E42: 5675453656 | F42: Dư Nợ cuối kỳ các TK 85, 86 | G42: như trên | M42: 8990362254
A43: c | B43: Dư có cuối kỳ TK 4620 | D43: ='so lieu'!G31 | E43: 1774591515 | F43: Dư Có cuối kỳ TK 4620 | G43: như trên | M43: 1679014356
...

Sheet B05
A1: Đơn vị: Ten cong ty Mẫu số : B05a/TCTD: BCTC riêng lẻ
A2: Địa chỉ: Dia chi
A4: THUYẾT MINH BÁO CÁO TÀI CHÍNH GIỮA NIÊN ĐỘ
A5: Quý I năm 2026
A7: I- Đặc điểm hoạt động của Đơn vị
A8: 1. Giấy phép thành lập và hoạt động, thời hạn có giá trị: 50 năm
A9: 2. Hình thức sở hữu vốn: 100% vốn do Ngân hàng TMCP Công thương VN góp vốn
A10: Vốn điều lệ của Đơn vị tại ngày 31 tháng 03 năm 2026 là: 50.000 triệu đồng
A11: 3. Thành phần Hội đồng quản trị: Bà Trần Thị Tuyết Mai - Chủ tịch công ty
A12: 4. Thành phần Ban Giám đốc:
A13: Ông Khổng Phan Đức – Tổng giám đốc
A14: Ông Đỗ Hữu Tụ - Phó Tổng giám đốc
... A53: 1. Tiền mặt, vàng bạc, đá quý
A54: Chỉ tiêu | B54: Số cuối kỳ | C54: Số đầu kỳ
A55: Tiền mặt bằng VND | B55: ='so lieu'!F1 | C55: ='B02'!E11
A56: Tiền mặt bằng ngoại tệ
A57: Chứng từ có giá trị ngoại tệ
A58: Vàng tiền tệ
A59: Kim loại đá quý khác
A60: Tổng | B60: =SUM(B55:B59) | C60: =C55 | D60: =B60-'B02'!D11
A61: - Dự phòng giảm giá trích lập đối với vàng phi tiền tệ, kim loại quý, đá quý (số dự phòng, cơ sở trích lập)
A62: 2. Tiền, vàng gửi tại TCTD khác
A63: Chỉ tiêu | B63: Số cuối kỳ | C63: Số đầu kỳ
A64: a. Tiền gửi không kỳ hạn | B64: =B65+B66 | C64: 187683604752
A65: - Bằng VND | B65: ='so lieu'!F2 | C65: 113672507448
A66: - Bằng ngoại tệ | B66: ='so lieu'!F4 | C66: 74011097304
A67: b. Tiền vàng gửi có kỳ hạn | B67: =B68 | C67: 70000000000
A68: - Bằng VND | B68: ='so lieu'!F3 | C68: 70000000000
A69: - Bằng ngoại tệ
A70: Tổng | B70: =B64+B67 | C70: 257683604752 | D70: =B70-'B02'!D14
A71: 3. Tài sản cố định hữu hình
A72: Khoản mục | B72: Máy móc thiết bị | C72: Phương tiện vận tải truyền dẫn | D72: Thiết bị dụng cụ quản lý | E72: TSCĐ khác | F72: Tổng cộng
A73: Nguyên giá
A74: Số dư đầu kỳ | B74: ='so lieu'!F5 | C74: ='so lieu'!F6 | D74: ='so lieu'!B7 | E74: ='so lieu'!B8 | F74: =SUM(B74:E74)
A75: Mua trong kỳ | B75: 0 | D75: =-'so lieu'!E7 | E75: =-'so lieu'!E8 | F75: =B75
A76: Số dư cuối kỳ | B76: =B74+B75 | C76: =C74+C75 | D76: =D74+D75 | E76: =E74+E75 | F76: =SUM(B76:E76) | G76: =F76-'B02'!D41
A77: Giá trị hao mòn lũy kế | F77: =B77
A78: Số dư đầu kỳ | B78: 118875001 | C78: 2356156363 | D78: 192222194 | E78: =E74 | F78: =SUM(B78:E78)
A79: Khấu hao trong kỳ | C79: =TSCD2025!L7+TSCD2025!L6 | D79: =TSCD2025!L9+TSCD2025!L10+TSCD2025!L11+TSCD2025!L12+TSCD2025!L13+TSCD2025!L14+D75 | E79: =E75 | F79: =SUM(B79:E79)
A80: Số dư cuối kỳ | B80: =B78+B79 | C80: =C78+C79 | D80: =D78+D79 | E80: =E78+E79 | F80: =SUM(B80:E80) | G80: =F80+'B02'!D42
...

Sheet Thue
A1: Ten cong ty - CTY me
A2: Dia chi
A4: TÌNH HÌNH THỰC HIỆN NGHĨA VỤ ĐỐI VỚI NHÀ NƯỚC
A5: Quý 1 năm 2026
M6: Đơn vị tính: VND
A8: Chỉ tiêu | B8: Mã số | D8: Số còn phải nộp kỳ trước chuyển sang | E8: Số phát sinh trong kỳ | G8: Số phát sinh lũy kế | M8: Số còn phải nộp cuối kỳ
E9: Số phải nộp | F9: Số đã nộp | G9: Số phải nộp | L9: Số đã nộp
A10: A | B10: B | D10: 1 | E10: 2 | F10: 3 | G10: 4 | L10: 5 | M10: 6
A11: I – Thuế | B11: 10 | D11: 2104207557 | E11: 2247355787 | F11: 3229324778 | G11: 2247355787 | L11: 3229324778 | M11: 1122238566
A12: 1. Thuế GTGT hàng bán nội địa | B12: 11 | D12: 327740170 | E12: 929981117 | F12: 924519785 | G12: 929981117 | L12: 924519785 | M12: 333201502
A13: 2. Thuế GTGT hàng nhập khẩu | B13: 12 | D13: 0 | E13: 0 | F13: 0 | G13: 0 | L13: 0 | M13: 0
A14: 3. Thuế tiêu thụ đặc biệt | B14: 13 | D14: 0 | E14: 0 | F14: 0 | G14: 0 | L14: 0 | M14: 0
A15: 4. Thuế xuất, nhập khẩu, chống bán phá giá | B15: 14 | D15: 0 | E15: 0 | F15: 0 | G15: 0 | L15: 0 | M15: 0
A16: 5. Thuế thu nhập doanh nghiệp | B16: 15 | D16: 1699375943 | E16: 778687531 | F16: 1699375943 | G16: 778687531 | L16: 1699375943 | M16: 778687531
A17: 6. Thuế thu nhập cá nhân | B17: 16 | D17: 77091444 | E17: 536486035 | F17: 603227946 | G17: 536486035 | L17: 603227946 | M17: 10349533
A18: 7. Thuế tài nguyên | B18: 17 | D18: 0 | E18: 0 | F18: 0 | G18: 0 | L18: 0 | M18: 0
A19: 8. Thuế nhà đất, tiền thuê đất | B19: 18 | D19: 0 | E19: 0 | F19: 0 | G19: 0 | L19: 0 | M19: 0
A20: 9. Thuế bảo vệ môi trường | B20: 19 | D20: 0 | E20: 0 | F20: 0 | G20: 0 | L20: 0 | M20: 0
A21: 10. Các loại thuế khác | B21: 20 | D21: 0 | E21: 2201104 | F21: 2201104 | G21: 2201104 | L21: 2201104 | M21: 0
A22: II – Các khoản phải nộp khác | B22: 30 | D22: 0 | E22: 0 | F22: 0 | G22: 0 | L22: 0 | M22: 0
... A26: Tổng cộng | B26: 40 | D26: 2104207557 | E26: 2247355787 | F26: 3229324778 | G26: 2247355787 | L26: 3229324778 | M26: 1122238566
A28: Người lập biểu | D28: Kế toán trưởng | I28: Giám đốc
A29: (Ký, ghi rõ họ tên) | D29: (Ký, ghi rõ họ tên) | I29: (Ký, đóng dấu, ghi rõ họ tên)
A31: Nguyễn Tuan Anh
A33: MISA SME

Sheet TSCD2025
A1: SỔ TÀI SẢN CỐ ĐỊNH
A2: Quý 1 năm 2026
A3: Mã TSCĐ | B3: Tên TSCĐ | C3: Loại TSCĐ | D3: Đơn vị sử dụng | E3: Ngày ghi tăng | F3: Số CT ghi tăng | G3: Ngày bắt đầu tính KH | H3: Thời gian SD (tháng) | I3: Thời gian SD còn lại (tháng) | J3: Nguyên giá | K3: Giá trị tính KH | L3: Hao mòn trong kỳ | M3: Hao mòn lũy kế | N3: Giá trị còn lại | O3: Giá trị KH tháng | P3: TK nguyên giá | Q3: TK khấu hao
A4: TSCĐ_PHOTO_002 | B4: Máy Photocopy Fuji XEROX Docucentre IV2060DD | C4: Máy móc, thiết bị | D4: PHÒNG TRIỂN KHAI SẢN PHẨM VÀ DV KHÁCH HÀNG | E4: 41190 | F4: OPN | G4: 41190 | H4: 36 | I4: 26 | J4: 58500000 | K4: 58500000 | M4: 58500000 | N4: 0 | O4: 1625000 | P4: 21121.01 | Q4: 21411.02
A5: TSCĐ_MAYCHIEU_X608_1 | B5: Máy chiếu HITACHI CP - X608 | C5: Máy móc, thiết bị | D5: PHÒNG KẾ TOÁN TÀI CHÍNH | E5: 41208 | F5: OPN | G5: 41208 | H5: 48 | I5: 38 | J5: 60375000 | K5: 60375000 | M5: 60375000 | N5: 0 | O5: 1257813 | P5: 21121.01 | Q5: 21411.02
A6: OTOCAMRY2.0 | B6: OTOCAMRY2.0 | C6: Phương tiện vận tải, truyền dẫn | D6: BAN GIÁM ĐỐC | E6: 42741 | F6: OTOCAMRY2.0 | G6: 42741 | H6: 96 | I6: 0 | J6: 1152821818 | K6: 1152821818 | M6: 1152821818 | N6: 0 | O6: 17482944 | P6: 21131.01 | Q6: 21411.01
A7: FORTUNER2.7V | B7: OTO FORTUNER 2.7V | C7: Phương tiện vận tải, truyền dẫn | D7: PHÒNG PHÁT TRIỂN KINH DOANH | E7: 43410 | F7: OTO FORTUNER 2.7V | G7: 43410 | H7: 72 | I7: 0 | J7: 1203334545 | K7: 1203334545 | M7: 1203334545 | N7: 0 | O7: 16712980 | P7: 21131.01 | Q7: 21411.01
A8: GHE SOFA | B8: GHE SOFA | C8: Tài sản cố định khác | D8: BAN GIÁM ĐỐC | E8: 43851 | F8: SOFA DA | G8: 43851 | H8: 48 | I8: 0 | J8: 70120000 | K8: 70120000 | M8: 70120000 | N8: 0 | O8: 1460833 | P8: 21181.01 | Q8: 21411.01
A9: iPAD Pro 12.9 220 | B9: ipad | C9: Thiết bị, dụng cụ quản lý | D9: BAN GIÁM ĐỐC | E9: 44189 | F9: iPAD Pro 12.9 220 | G9: 44189 | H9: 36 | I9: 0 | J9: 32718182 | K9: 32718182 | M9: 32718182 | N9: 0 | O9: 908838 | P9: 21141.01 | Q9: 21411.02
A10: Máy photocopy Ricoh | B10: Máy photocopy Ricoh | C10: Thiết bị, dụng cụ quản lý | D10: PHÒNG PHÁT TRIỂN KINH DOANH | E10: 44196 | F10: Máy photocopy Ricoh | G10: 44196 | H10: 36 | I10: 0 | J10: 44590909 | K10: 44590909 | M10: 44590909 | N10: 0 | O10: 1238636 | P10: 21141.01 | Q10: 21411.02
A11: ĐTDĐ Samsung Galaxy Z | B11: ĐTDĐ Samsung Galaxy Z Fold 3 5G 512GB Phantom black | C11: Thiết bị, dụng cụ quản lý | D11: BAN GIÁM ĐỐC | E11: 44456 | F11: ĐTDĐ Samsung Galaxy | G11: 44456 | H11: 36 | I11: 0 | J11: 40900000 | K11: 40900000 | M11: 40900000 | N11: 0 | O11: 1136111 | P11: 21141.01 | Q11: 21411.02
A12: CISCO | B12: Thiết bị hội nghị truyền hình CISCO SX10 CTS-SX10N-K9 | C12: Máy móc, thiết bị | D12: PHÒNG HỌP | E12: 44539 | F12: CISCO | G12: 44539 | H12: 36 | I12: 0 | J12: 46000000 | K12: 46000000 | M12: 46000000 | N12: 0 | O12: 1277778 | P12: 21141.01 | Q12: 21411.02
A13: Máy tính xách tay Lenovo | B13: Máy tính xách tay Lenovo ThinkPad T14S GEN4 | C13: Thiết bị, dụng cụ quản lý | D13: BAN GIÁM ĐỐC | E13: 45576 | F13: LENOVO | G13: 45576 | H13: 36 | I13: 18 | J13: 33445455 | K13: 33445455 | L13: 2787120 | M13: 16423030 | N13: 17022425 | O13: 929040 | P13: 21141.01 | Q13: 21411.01
A14: Máy tính xách tay LG Gram | B14: Máy tính xách tay LG Gram 14Z90S G.AH75A5 | C14: Thiết bị, dụng cụ quản lý | D14: BAN GIÁM ĐỐC | E14: 45576 | F14: LG Gram | G14: 45576 | H14: 36 | I14: 18 | J14: 35263636 | K14: 35263636 | L14: 2938635 | M14: 17315828 | N14: 17947808 | O14: 979545 | P14: 21141.01 | Q14: 21411.01
A15: Số dòng = 11 | H15: 516 | I15: 100 | J15: 2778069545 | K15: 2778069545 | L15: 5725755 | M15: 2743099312 | N15: 34970233 | O15: 45009518

Sheet so lieu
A1: 101101 | B1: 310486901 | C1: 0 | D1: 382976974 | E1: 331744738 | F1: 361719137 | G1: 0 | H1: NOTE | K1: =VLOOKUP($A1,[3]Sheet1!$A:$J,3,0) | L1: =VLOOKUP($A1,[3]Sheet1!$A:$J,4,0) | M1: =VLOOKUP($A1,[3]Sheet1!$A:$J,5,0) | N1: =VLOOKUP($A1,[3]Sheet1!$A:$J,6,0) | O1: =VLOOKUP($A1,[3]Sheet1!$A:$J,7,0) | P1: =VLOOKUP($A1,[3]Sheet1!$A:$J,8,0) | R1: =K1-B1 | S1: =L1-C1 | T1: =M1-D1 | U1: =N1-E1 | V1: =O1-F1 | W1: =P1-G1
A2: 131101 | B2: 299738414128 | C2: 0 | D2: =10364202871348+'But toan can tru'!D25 | E2: 10589466947147 | F2: =74474338329+'But toan can tru'!D25 | G2: 0 | H2: Cấn trừ | I2: =B2-E2+D2-F2 | K2: =VLOOKUP($A2,[3]Sheet1!$A:$J,3,0) | L2: =VLOOKUP($A2,[3]Sheet1!$A:$J,4,0) | M2: =VLOOKUP($A2,[3]Sheet1!$A:$J,5,0) | N2: =VLOOKUP($A2,[3]Sheet1!$A:$J,6,0) | O2: =VLOOKUP($A2,[3]Sheet1!$A:$J,7,0) | P2: =VLOOKUP($A2,[3]Sheet1!$A:$J,8,0) | R2: =K2-B2 | S2: =L2-C2 | T2: =M2-D2 | U2: =N2-E2 | V2: =O2-F2 | W2: =P2-G2
A3: 131201 | B3: 58000000000 | C3: 0 | D3: 57000000000 | E3: 50000000000 | F3: 65000000000 | G3: 0 | K3: =VLOOKUP($A3,[3]Sheet1!$A:$J,3,0) | L3: =VLOOKUP($A3,[3]Sheet1!$A:$J,4,0) | M3: =VLOOKUP($A3,[3]Sheet1!$A:$J,5,0) | N3: =VLOOKUP($A3,[3]Sheet1!$A:$J,6,0) | O3: =VLOOKUP($A3,[3]Sheet1!$A:$J,7,0) | P3: =VLOOKUP($A3,[3]Sheet1!$A:$J,8,0) | R3: =K3-B3 | S3: =L3-C3 | T3: =M3-D3 | U3: =N3-E3 | V3: =O3-F3 | W3: =P3-G3
A4: 132101 | B4: 39966905479 | C4: 0 | D4: 8196460662442 | E4: 8189592093757 | F4: 46835474164 | G4: 0 | K4: =VLOOKUP($A4,[3]Sheet1!$A:$J,3,0) | L4: =VLOOKUP($A4,[3]Sheet1!$A:$J,4,0) | M4: =VLOOKUP($A4,[3]Sheet1!$A:$J,5,0) | N4: =VLOOKUP($A4,[3]Sheet1!$A:$J,6,0) | O4: =VLOOKUP($A4,[3]Sheet1!$A:$J,7,0) | P4: =VLOOKUP($A4,[3]Sheet1!$A:$J,8,0) | R4: =K4-B4 | S4: =L4-C4 | T4: =M4-D4 | U4: =N4-E4 | V4: =O4-F4 | W4: =P4-G4
A5: 301301 | B5: 118875001 | C5: 0 | D5: 0 | E5: 0 | F5: 118875001 | G5: 0 | K5: =VLOOKUP($A5,[3]Sheet1!$A:$J,3,0) | L5: =VLOOKUP($A5,[3]Sheet1!$A:$J,4,0) | M5: =VLOOKUP($A5,[3]Sheet1!$A:$J,5,0) | N5: =VLOOKUP($A5,[3]Sheet1!$A:$J,6,0) | O5: =VLOOKUP($A5,[3]Sheet1!$A:$J,7,0) | P5: =VLOOKUP($A5,[3]Sheet1!$A:$J,8,0) | R5: =K5-B5 | S5: =L5-C5 | T5: =M5-D5 | U5: =N5-E5 | V5: =O5-F5 | W5: =P5-G5
A6: 301401 | B6: 2356156363 | C6: 0 | D6: 0 | E6: 0 | F6: 2356156363 | G6: 0 | K6: =VLOOKUP($A6,[3]Sheet1!$A:$J,3,0) | L6: =VLOOKUP($A6,[3]Sheet1!$A:$J,4,0) | M6: =VLOOKUP($A6,[3]Sheet1!$A:$J,5,0) | N6: =VLOOKUP($A6,[3]Sheet1!$A:$J,6,0) | O6: =VLOOKUP($A6,[3]Sheet1!$A:$J,7,0) | P6: =VLOOKUP($A6,[3]Sheet1!$A:$J,8,0) | R6: =K6-B6 | S6: =L6-C6 | T6: =M6-D6 | U6: =N6-E6 | V6: =O6-F6 | W6: =P6-G6
A7: 301501 | B7: 232918182 | C7: 0 | D7: 0 | E7: 32718182 | F7: 200200000 | G7: 0 | K7: =VLOOKUP($A7,[3]Sheet1!$A:$J,3,0) | L7: =VLOOKUP($A7,[3]Sheet1!$A:$J,4,0) | M7: =VLOOKUP($A7,[3]Sheet1!$A:$J,5,0) | N7: =VLOOKUP($A7,[3]Sheet1!$A:$J,6,0) | O7: =VLOOKUP($A7,[3]Sheet1!$A:$J,7,0) | P7: =VLOOKUP($A7,[3]Sheet1!$A:$J,8,0) | R7: =K7-B7 | S7: =L7-C7 | T7: =M7-D7 | U7: =N7-E7 | V7: =O7-F7 | W7: =P7-G7
A8: 301902 | B8: 70120000 | C8: 0 | D8: 0 | E8: 70120000 | F8: 0 | G8: 0 | K8: =VLOOKUP($A8,[3]Sheet1!$A:$J,3,0) | L8: =VLOOKUP($A8,[3]Sheet1!$A:$J,4,0) | M8: =VLOOKUP($A8,[3]Sheet1!$A:$J,5,0) | N8: =VLOOKUP($A8,[3]Sheet1!$A:$J,6,0) | O8: =VLOOKUP($A8,[3]Sheet1!$A:$J,7,0) | P8: =VLOOKUP($A8,[3]Sheet1!$A:$J,8,0) | R8: =K8-B8 | S8: =L8-C8 | T8: =M8-D8 | U8: =N8-E8 | V8: =O8-F8 | W8: =P8-G8
A9: 305101 | B9: 0 | C9: 2454289467 | D9: 70120000 | E9: 5725755 | F9: 0 | G9: 2389895222 | H9: 13885.02 | I9: 44528683328 | K9: =VLOOKUP($A9,[3]Sheet1!$A:$J,3,0) | L9: =VLOOKUP($A9,[3]Sheet1!$A:$J,4,0) | M9: =VLOOKUP($A9,[3]Sheet1!$A:$J,5,0) | N9: =VLOOKUP($A9,[3]Sheet1!$A:$J,6,0) | O9: =VLOOKUP($A9,[3]Sheet1!$A:$J,7,0) | P9: =VLOOKUP($A9,[3]Sheet1!$A:$J,8,0) | R9: =K9-B9 | S9: =L9-C9 | T9: =M9-D9 | U9: =N9-E9 | V9: =O9-F9 | W9: =P9-G9
A10: 305102 | B10: 0 | C10: 283084091 | D10: 32718182 | E10: 0 | F10: 0 | G10: 250365909 | I10: =SUM(F5:F8) | K10: =VLOOKUP($A10,[3]Sheet1!$A:$J,3,0) | L10: =VLOOKUP($A10,[3]Sheet1!$A:$J,4,0) | M10: =VLOOKUP($A10,[3]Sheet1!$A:$J,5,0) | N10: =VLOOKUP($A10,[3]Sheet1!$A:$J,6,0) | O10: =VLOOKUP($A10,[3]Sheet1!$A:$J,7,0) | P10: =VLOOKUP($A10,[3]Sheet1!$A:$J,8,0) | R10: =K10-B10 | S10: =L10-C10 | T10: =M10-D10 | U10: =N10-E10 | V10: =O10-F10 | W10: =P10-G10
A11: 311001 | B11: 0 | C11: 0 | D11: 0 | E11: 0 | F11: 0 | G11: 0 | R11: =K11-B11 | S11: =L11-C11 | T11: =M11-D11 | U11: =N11-E11 | V11: =O11-F11 | W11: =P11-G11
A12: 313001 | B12: 0 | C12: 0 | D12: 0 | E12: 0 | F12: 0 | G12: 0 | R12: =K12-B12 | S12: =L12-C12 | T12: =M12-D12 | U12: =N12-E12 | V12: =O12-F12 | W12: =P12-G12
A13: 351001 | B13: 15000000 | C13: 0 | D13: 0 | E13: 0 | F13: 15000000 | G13: 0 | K13: =VLOOKUP($A13,[3]Sheet1!$A:$J,3,0) | L13: =VLOOKUP($A13,[3]Sheet1!$A:$J,4,0) | M13: =VLOOKUP($A13,[3]Sheet1!$A:$J,5,0) | N13: =VLOOKUP($A13,[3]Sheet1!$A:$J,6,0) | O13: =VLOOKUP($A13,[3]Sheet1!$A:$J,7,0) | P13: =VLOOKUP($A13,[3]Sheet1!$A:$J,8,0) | R13: =K13-B13 | S13: =L13-C13 | T13: =M13-D13 | U13: =N13-E13 | V13: =O13-F13 | W13: =P13-G13
A14: 353202 | B14: 0 | C14: 0 | D14: 286565983 | E14: 286565983 | F14: 0 | G14: 0 | K14: =VLOOKUP($A14,[3]Sheet1!$A:$J,3,0) | L14: =VLOOKUP($A14,[3]Sheet1!$A:$J,4,0) | M14: =VLOOKUP($A14,[3]Sheet1!$A:$J,5,0) | N14: =VLOOKUP($A14,[3]Sheet1!$A:$J,6,0) | O14: =VLOOKUP($A14,[3]Sheet1!$A:$J,7,0) | P14: =VLOOKUP($A14,[3]Sheet1!$A:$J,8,0) | R14: =K14-B14 | S14: =L14-C14 | T14: =M14-D14 | U14: =N14-E14 | V14: =O14-F14 | W14: =P14-G14
A15: 359299 | B15: 37683655715 | C15: 0 | D15: 1552255225911 | E15: =1561472090459+'But toan can tru'!D27+'But toan can tru'!D7 | F15: =28466791167-'But toan can tru'!D25-'But toan can tru'!D7 | G15: 0 | H15: Cấn trừ | I15: =B15-E15+D15-F15 | K15: =VLOOKUP($A15,[3]Sheet1!$A:$J,3,0) | L15: =VLOOKUP($A15,[3]Sheet1!$A:$J,4,0) | M15: =VLOOKUP($A15,[3]Sheet1!$A:$J,5,0) | N15: =VLOOKUP($A15,[3]Sheet1!$A:$J,6,0) | O15: =VLOOKUP($A15,[3]Sheet1!$A:$J,7,0) | P15: =VLOOKUP($A15,[3]Sheet1!$A:$J,8,0) | R15: =K15-B15 | S15: =L15-C15 | T15: =M15-D15 | U15: =N15-E15 | V15: =O15-F15 | W15: =P15-G15
A16: 361207 | B16: 0 | C16: 0 | D16: 0 | E16: 0 | F16: 0 | G16: 0 | R16: =K16-B16 | S16: =L16-C16 | T16: =M16-D16 | U16: =N16-E16 | V16: =O16-F16 | W16: =P16-G16
A17: 361299 | B17: 0 | C17: 0 | D17: 27000000 | E17: 27000000 | F17: 0 | G17: 0 | K17: =VLOOKUP($A17,[3]Sheet1!$A:$J,3,0) | L17: =VLOOKUP($A17,[3]Sheet1!$A:$J,4,0) | M17: =VLOOKUP($A17,[3]Sheet1!$A:$J,5,0) | N17: =VLOOKUP($A17,[3]Sheet1!$A:$J,6,0) | O17: =VLOOKUP($A17,[3]Sheet1!$A:$J,7,0) | P17: =VLOOKUP($A17,[3]Sheet1!$A:$J,8,0) | R17: =K17-B17 | S17: =L17-C17 | T17: =M17-D17 | U17: =N17-E17 | V17: =O17-F17 | W17: =P17-G17
A18: 361301 | B18: 0 | C18: 0 | D18: 0 | E18: 0 | F18: 0 | G18: 0 | R18: =K18-B18 | S18: =L18-C18 | T18: =M18-D18 | U18: =N18-E18 | V18: =O18-F18 | W18: =P18-G18
A19: 388009 | B19: 234576000 | C19: 0 | D19: 0 | E19: 175932000 | F19: 58644000 | G19: 0 | K19: =VLOOKUP($A19,[3]Sheet1!$A:$J,3,0) | L19: =VLOOKUP($A19,[3]Sheet1!$A:$J,4,0) | M19: =VLOOKUP($A19,[3]Sheet1!$A:$J,5,0) | N19: =VLOOKUP($A19,[3]Sheet1!$A:$J,6,0) | O19: =VLOOKUP($A19,[3]Sheet1!$A:$J,7,0) | P19: =VLOOKUP($A19,[3]Sheet1!$A:$J,8,0) | R19: =K19-B19 | S19: =L19-C19 | T19: =M19-D19 | U19: =N19-E19 | V19: =O19-F19 | W19: =P19-G19
A20: 391 | B20: 1590082190 | C20: 0 | D20: 671024661 | E20: 1225983562 | F20: 1035123289 | G20: 0 | I20: =B20+D20-E20-F20 | K20: =VLOOKUP($A20,[3]Sheet1!$A:$J,3,0) | L20: =VLOOKUP($A20,[3]Sheet1!$A:$J,4,0) | M20: =VLOOKUP($A20,[3]Sheet1!$A:$J,5,0) | N20: =VLOOKUP($A20,[3]Sheet1!$A:$J,6,0) | O20: =VLOOKUP($A20,[3]Sheet1!$A:$J,7,0) | P20: =VLOOKUP($A20,[3]Sheet1!$A:$J,8,0) | R20: =K20-B20 | S20: =L20-C20 | T20: =M20-D20 | U20: =N20-E20 | V20: =O20-F20 | W20: =P20-G20
A21: 397001 | B21: 2773205015 | C21: 0 | D21: 8240055269 | E21: 8309975995 | F21: 2703284289 | I21: =B21+D21-E21-F21
A22: 427909 | B22: 0 | C22: 0 | D22: 21723240 | E22: 21723240 | F22: 0 | G22: 0 | K22: =VLOOKUP($A22,[3]Sheet1!$A:$J,3,0) | L22: =VLOOKUP($A22,[3]Sheet1!$A:$J,4,0) | M22: =VLOOKUP($A22,[3]Sheet1!$A:$J,5,0) | N22: =VLOOKUP($A22,[3]Sheet1!$A:$J,6,0) | O22: =VLOOKUP($A22,[3]Sheet1!$A:$J,7,0) | P22: =VLOOKUP($A22,[3]Sheet1!$A:$J,8,0) | R22: =K22-B22 | S22: =L22-C22 | T22: =M22-D22 | U22: =N22-E22 | V22: =O22-F22 | W22: =P22-G22
A23: 453101 | B23: 0 | C23: 327740170 | D23: 1211085768 | E23: 1216547100 | F23: 0 | G23: 333201502 | K23: =VLOOKUP($A23,[3]Sheet1!$A:$J,3,0) | L23: =VLOOKUP($A23,[3]Sheet1!$A:$J,4,0) | M23: =VLOOKUP($A23,[3]Sheet1!$A:$J,5,0) | N23: =VLOOKUP($A23,[3]Sheet1!$A:$J,6,0) | O23: =VLOOKUP($A23,[3]Sheet1!$A:$J,7,0) | P23: =VLOOKUP($A23,[3]Sheet1!$A:$J,8,0) | R23: =K23-B23 | S23: =L23-C23 | T23: =M23-D23 | U23: =N23-E23 | V23: =O23-F23 | W23: =P23-G23
A24: 453401 | B24: 0 | C24: 1699375943 | D24: 1699375943 | E24: 778687531 | F24: 0 | G24: 778687531 | K24: =VLOOKUP($A24,[3]Sheet1!$A:$J,3,0) | L24: =VLOOKUP($A24,[3]Sheet1!$A:$J,4,0) | M24: =VLOOKUP($A24,[3]Sheet1!$A:$J,5,0) | N24: =VLOOKUP($A24,[3]Sheet1!$A:$J,6,0) | O24: =VLOOKUP($A24,[3]Sheet1!$A:$J,7,0) | P24: =VLOOKUP($A24,[3]Sheet1!$A:$J,8,0) | R24: =K24-B24 | S24: =L24-C24 | T24: =M24-D24 | U24: =N24-E24 | V24: =O24-F24 | W24: =P24-G24
A25: 453801 | B25: 0 | C25: 0 | D25: 2201104 | E25: 2201104 | F25: 0 | G25: 0 | K25: =VLOOKUP($A25,[3]Sheet1!$A:$J,3,0) | L25: =VLOOKUP($A25,[3]Sheet1!$A:$J,4,0) | M25: =VLOOKUP($A25,[3]Sheet1!$A:$J,5,0) | N25: =VLOOKUP($A25,[3]Sheet1!$A:$J,6,0) | O25: =VLOOKUP($A25,[3]Sheet1!$A:$J,7,0) | P25: =VLOOKUP($A25,[3]Sheet1!$A:$J,8,0) | R25: =K25-B25 | S25: =L25-C25 | T25: =M25-D25 | U25: =N25-E25 | V25: =O25-F25 | W25: =P25-G25
A26: 453802 | B26: 0 | C26: 77091444 | D26: 603227946 | E26: 536486035 | F26: 0 | G26: 10349533 | K26: =VLOOKUP($A26,[3]Sheet1!$A:$J,3,0) | L26: =VLOOKUP($A26,[3]Sheet1!$A:$J,4,0) | M26: =VLOOKUP($A26,[3]Sheet1!$A:$J,5,0) | N26: =VLOOKUP($A26,[3]Sheet1!$A:$J,6,0) | O26: =VLOOKUP($A26,[3]Sheet1!$A:$J,7,0) | P26: =VLOOKUP($A26,[3]Sheet1!$A:$J,8,0) | R26: =K26-B26 | S26: =L26-C26 | T26: =M26-D26 | U26: =N26-E26 | V26: =O26-F26 | W26: =P26-G26
A27: 453901 | B27: 0 | C27: 0 | D27: 0 | E27: 0 | F27: 0 | G27: 0 | R27: =K27-B27 | S27: =L27-C27 | T27: =M27-D27 | U27: =N27-E27 | V27: =O27-F27 | W27: =P27-G27
A28: 454001 | B28: 0 | C28: 298689875593 | D28: 7865075540635 | E28: 7638444949765 | F28: 0 | G28: 72059284723 | K28: =VLOOKUP($A28,[3]Sheet1!$A:$J,3,0) | L28: =VLOOKUP($A28,[3]Sheet1!$A:$J,4,0) | M28: =VLOOKUP($A28,[3]Sheet1!$A:$J,5,0) | N28: =VLOOKUP($A28,[3]Sheet1!$A:$J,6,0) | O28: =VLOOKUP($A28,[3]Sheet1!$A:$J,7,0) | P28: =VLOOKUP($A28,[3]Sheet1!$A:$J,8,0) | R28: =K28-B28 | S28: =L28-C28 | T28: =M28-D28 | U28: =N28-E28 | V28: =O28-F28 | W28: =P28-G28
A29: 459908 | B29: 0 | C29: 1552685577 | D29: 163640000 | E29: 721837270 | F29: 0 | G29: 2110882847 | K29: =VLOOKUP($A29,[3]Sheet1!$A:$J,3,0) | L29: =VLOOKUP($A29,[3]Sheet1!$A:$J,4,0) | M29: =VLOOKUP($A29,[3]Sheet1!$A:$J,5,0) | N29: =VLOOKUP($A29,[3]Sheet1!$A:$J,6,0) | O29: =VLOOKUP($A29,[3]Sheet1!$A:$J,7,0) | P29: =VLOOKUP($A29,[3]Sheet1!$A:$J,8,0) | R29: =K29-B29 | S29: =L29-C29 | T29: =M29-D29 | U29: =N29-E29 | V29: =O29-F29 | W29: =P29-G29
A30: 459999 | B30: 0 | C30: 54938713654 | D30: 10852458371657 | E30: =10858679850671-'But toan can tru'!D8 | F30: 0 | G30: =61160192668-'But toan can tru'!D7 | H30: Cấn trừ | I30: =C30+E30-D30-G30 | K30: =VLOOKUP($A30,[3]Sheet1!$A:$J,3,0) | L30: =VLOOKUP($A30,[3]Sheet1!$A:$J,4,0) | M30: =VLOOKUP($A30,[3]Sheet1!$A:$J,5,0) | N30: =VLOOKUP($A30,[3]Sheet1!$A:$J,6,0) | O30: =VLOOKUP($A30,[3]Sheet1!$A:$J,7,0) | P30: =VLOOKUP($A30,[3]Sheet1!$A:$J,8,0) | R30: =K30-B30 | S30: =L30-C30 | T30: =M30-D30 | U30: =N30-E30 | V30: =O30-F30 | W30: =P30-G30
A31: 462001 | B31: 0 | C31: 5432454882 | D31: 7111945353 | E31: 3897402000 | F31: 0 | G31: 2217911529 | K31: =VLOOKUP($A31,[3]Sheet1!$A:$J,3,0) | L31: =VLOOKUP($A31,[3]Sheet1!$A:$J,4,0) | M31: =VLOOKUP($A31,[3]Sheet1!$A:$J,5,0) | N31: =VLOOKUP($A31,[3]Sheet1!$A:$J,6,0) | O31: =VLOOKUP($A31,[3]Sheet1!$A:$J,7,0) | P31: =VLOOKUP($A31,[3]Sheet1!$A:$J,8,0) | R31: =K31-B31 | S31: =L31-C31 | T31: =M31-D31 | U31: =N31-E31 | V31: =O31-F31 | W31: =P31-G31
A32: 484101 | B32: 0 | C32: 448921461 | D32: 420000000 | E32: 0 | F32: 0 | G32: 28921461 | K32: =VLOOKUP($A32,[3]Sheet1!$A:$J,3,0) | L32: =VLOOKUP($A32,[3]Sheet1!$A:$J,4,0) | M32: =VLOOKUP($A32,[3]Sheet1!$A:$J,5,0) | N32: =VLOOKUP($A32,[3]Sheet1!$A:$J,6,0) | O32: =VLOOKUP($A32,[3]Sheet1!$A:$J,7,0) | P32: =VLOOKUP($A32,[3]Sheet1!$A:$J,8,0) | R32: =K32-B32 | S32: =L32-C32 | T32: =M32-D32 | U32: =N32-E32 | V32: =O32-F32 | W32: =P32-G32
A33: 484201 | B33: 0 | C33: 89214568 | D33: 0 | E33: 0 | F33: 0 | G33: 89214568 | K33: =VLOOKUP($A33,[3]Sheet1!$A:$J,3,0) | L33: =VLOOKUP($A33,[3]Sheet1!$A:$J,4,0) | M33: =VLOOKUP($A33,[3]Sheet1!$A:$J,5,0) | N33: =VLOOKUP($A33,[3]Sheet1!$A:$J,6,0) | O33: =VLOOKUP($A33,[3]Sheet1!$A:$J,7,0) | P33: =VLOOKUP($A33,[3]Sheet1!$A:$J,8,0) | R33: =K33-B33 | S33: =L33-C33 | T33: =M33-D33 | U33: =N33-E33 | V33: =O33-F33 | W33: =P33-G33
B34: 0 | C34: 0 | D34: 0 | E34: 0 | F34: 0 | G34: 0 | R34: =K34-B34 | S34: =L34-C34 | T34: =M34-D34 | U34: =N34-E34 | V34: =O34-F34 | W34: =P34-G34
A35: 497001 | B35: 0 | C35: 0 | D35: 5692347573 | E35: 5692347573 | F35: 0 | G35: 0 | K35: =VLOOKUP($A35,[3]Sheet1!$A:$J,3,0) | L35: =VLOOKUP($A35,[3]Sheet1!$A:$J,4,0) | M35: =VLOOKUP($A35,[3]Sheet1!$A:$J,5,0) | N35: =VLOOKUP($A35,[3]Sheet1!$A:$J,6,0) | O35: =VLOOKUP($A35,[3]Sheet1!$A:$J,7,0) | P35: =VLOOKUP($A35,[3]Sheet1!$A:$J,8,0) | R35: =K35-B35 | S35: =L35-C35 | T35: =M35-D35 | U35: =N35-E35 | V35: =O35-F35 | W35: =P35-G35
A36: 601001 | B36: 0 | C36: 50000000000 | D36: 0 | E36: 0 | F36: 0 | G36: 50000000000 | K36: =VLOOKUP($A36,[3]Sheet1!$A:$J,3,0) | L36: =VLOOKUP($A36,[3]Sheet1!$A:$J,4,0) | M36: =VLOOKUP($A36,[3]Sheet1!$A:$J,5,0) | N36: =VLOOKUP($A36,[3]Sheet1!$A:$J,6,0) | O36: =VLOOKUP($A36,[3]Sheet1!$A:$J,7,0) | P36: =VLOOKUP($A36,[3]Sheet1!$A:$J,8,0) | R36: =K36-B36 | S36: =L36-C36 | T36: =M36-D36 | U36: =N36-E36 | V36: =O36-F36 | W36: =P36-G36
A37: 611001 | B37: 0 | C37: 3793255874 | D37: 0 | E37: 0 | F37: 0 | G37: 3793255874 | K37: =VLOOKUP($A37,[3]Sheet1!$A:$J,3,0) | L37: =VLOOKUP($A37,[3]Sheet1!$A:$J,4,0) | M37: =VLOOKUP($A37,[3]Sheet1!$A:$J,5,0) | N37: =VLOOKUP($A37,[3]Sheet1!$A:$J,6,0) | O37: =VLOOKUP($A37,[3]Sheet1!$A:$J,7,0) | P37: =VLOOKUP($A37,[3]Sheet1!$A:$J,8,0) | R37: =K37-B37 | S37: =L37-C37 | T37: =M37-D37 | U37: =N37-E37 | V37: =O37-F37 | W37: =P37-G37
A38: 612101 | B38: 0 | C38: 5336258205 | D38: 0 | E38: 0 | F38: 0 | G38: 5336258205 | K38: =VLOOKUP($A38,[3]Sheet1!$A:$J,3,0) | L38: =VLOOKUP($A38,[3]Sheet1!$A:$J,4,0) | M38: =VLOOKUP($A38,[3]Sheet1!$A:$J,5,0) | N38: =VLOOKUP($A38,[3]Sheet1!$A:$J,6,0) | O38: =VLOOKUP($A38,[3]Sheet1!$A:$J,7,0) | P38: =VLOOKUP($A38,[3]Sheet1!$A:$J,8,0) | R38: =K38-B38 | S38: =L38-C38 | T38: =M38-D38 | U38: =N38-E38 | V38: =O38-F38 | W38: =P38-G38
A39: 631101 | B39: 0 | C39: 0 | D39: 181114870 | E39: 181114870 | F39: 0 | G39: 0 | K39: =VLOOKUP($A39,[3]Sheet1!$A:$J,3,0) | L39: =VLOOKUP($A39,[3]Sheet1!$A:$J,4,0) | M39: =VLOOKUP($A39,[3]Sheet1!$A:$J,5,0) | N39: =VLOOKUP($A39,[3]Sheet1!$A:$J,6,0) | O39: =VLOOKUP($A39,[3]Sheet1!$A:$J,7,0) | P39: =VLOOKUP($A39,[3]Sheet1!$A:$J,8,0) | R39: =K39-B39 | S39: =L39-C39 | T39: =M39-D39 | U39: =N39-E39 | V39: =O39-F39 | W39: =P39-G39
A40: 691001 | B40: 0 | C40: 17967434045 | D40: 17967434045 | E40: 0 | F40: 0 | G40: 0 | R40: =K40-B40 | S40: =L40-C40 | T40: =M40-D40 | U40: =N40-E40 | V40: =O40-F40 | W40: =P40-G40
...

Sheet But toan can tru
A2: Account | B2: Tên tài khoản | C2: TK SBV | D2: Amount
A3: Cấn trừ phải thu phải trả WU
A4: 13882.02 | B4: Phải thu Western Union - Ngoại tệ | D4: 0 | E4: -
A5: 33882.01 | B5: Phải trả Western Union - VNĐ | D5: =-D4
A6: Cấn trừ tài khoản trung gian mua bán ngoại tệ
A7: Nợ TK 33886.02 | B7: Phải trả, phải nộp khác_Ngoại tệ | C7: 4599 | D7: 5375167887
A8: Có TK 13885.02 | B8: Các khoản phải thu khác - Ngoại tệ | C8: 3592 | D8: =D7
A9: Cấn trừ các tài khoản WASH
A10: Có TK 1121 | B10: Tiền gửi VND | C10: 1311 | D10: 0
A11: Nợ TK 33883.01 | B11: Kiều hối phải trả VND | C11: 4540 | D11: =D10
A12: Có TK 1122 | B12: Tiền gửi ngoại tệ | C12: 1311 | D12: 0
A13: Nợ TK 33884.02 | B13: Phải trả đối tác - Ngoại tệ | C13: 4599 | D13: =D12
A14: Cấn trừ phải thu phải trả với
A15: Có TK 13881 | B15: Phải thu của | C15: 3592
A16: Nợ TK 112 | B16: Tiền gửi ngoại tệ | C16: 1311
A17: Cấn trừ phải thu phải trả với WU
A18: Có TK 13882 | B18: Phải thu WU | C18: 3592
A19: Nợ TK 112 | B19: Tiền gửi ngoại tệ | C19: 1311
A20: Cấn trừ phải thu phải trả với WU
A21: Có TK 112 | B21: Tiền gửi ngoại tệ | C21: 1311
A22: Nợ TK 33882.02 | B22: Phải trả WU | C22: 4599
A24: Chuyển phải thu của về tiền gửi
A25: Nợ TK 112 | B25: Tiền gửi ngoại tệ | C25: 1311 | D25: =D27
A26: Nợ TK 33882.02 | B26: Phải trả WU | C26: 4599 | D26: 0
A27: Có TK 13881 | B27: Phải thu của | C27: 3592 | D27: 13161293262
A28: Có TK 13882 | B28: Phải thu WU | C28: 3592 | D28: 0
A30: Ghi nhận lại tài khoản WASH vào tiền gửi và phải trả đối tác
A31: Nợ TK 112 | B31: Tiền gửi ngoại tệ | C31: 1311
A32: Có TK 33884.02 | B32: Phải trả đối tác - Ngoại tệ | C32: 4599
A33: Có TK 33883.01 | B33: Phải trả đối tác - VND | C33: 4599

Sheet Sổ chi tiết TK LN
A1: SỔ CHI TIẾT CÁC TÀI KHOẢN
A2: Loại tiền: Tổng hợp; Tài khoản: 421; Quý 1 năm 2026
A3: Ngày hạch toán | B3: Ngày chứng từ | C3: Số chứng từ | D3: Diễn giải | E3: Tài khoản | F3: TK đối ứng | G3: Phát sinh Nợ | I3: Phát sinh Có | K3: Dư Nợ | M3: Dư Có | O3: Mã mục thu/chi | P3: Tên mục thu/chi
G4: Số tiền | H4: Quy đổi | I4: Số tiền | J4: Quy đổi | K4: Số tiền | L4: Quy đổi | M4: Số tiền | N4: Quy đổi
D5: Số dư đầu kỳ | E5: 421 | K5: 0 | L5: 0 | M5: 17967434045 | N5: 17967434045
A6: 46027 | B6: 46027 | C6: ZKC01 | D6: Kết chuyển lợi nhuận sau thuế năm 2025 | E6: 421 | F6: 42121.01 | G6: 0 | H6: 0 | I6: 17967434045 | J6: 17967434045 | K6: 0 | L6: 0 | M6: 35934868090 | N6: 35934868090
A7: 46027 | B7: 46027 | C7: ZKC01 | D7: Kết chuyển lợi nhuận sau thuế năm 2025 | E7: 421 | F7: 42111.01 | G7: 17967434045 | H7: 17967434045 | I7: 0 | J7: 0 | K7: 0 | L7: 0 | M7: 17967434045 | N7: 17967434045
D8: Cộng | E8: 421 | G8: 17967434045 | H8: 17967434045 | I8: 17967434045 | J8: 17967434045
D9: Số dư cuối kỳ | E9: 421 | K9: 0 | L9: 0 | M9: 17967434045 | N9: 17967434045
A10: Số dòng = 5 | G10: 17967434045 | H10: 17967434045 | I10: 17967434045 | J10: 17967434045

Sheet Thuế TNDN Q4
A1: Ten cong ty
A2: PHÒNG TÀI CHÍNH KẾ TOÁN
A4: BẢNG TÍNH THUẾ THU NHẬP DOANH NGHIỆP TẠM TÍNH Quý 1 năm 2026
B6: STT | C6: Nội Dung | D6: Số tiền
B7: 1 | C7: Doanh thu Quý 1 năm 2026 | D7: =SUM(D8:D10)
C8: Doanh thu phí Quý 1 năm 2026 | D8: =[5]Sheet24!R31
C9: Doanh thu tài chính Quý 1 năm 2026 | D9: =[5]Sheet24!R32
C10: Thu nhập khác Quý 1 năm 2026 | D10: 0
B11: 2 | C11: Chi phí Quý 1 năm 2026 | D11: =SUM(D12:D16) | E11: Lợi nhuận trước thuế | F11: =D7-D11
C12: Giá vốn hàng bán Quý 1 năm 2026 | D12: =[5]Sheet24!P33
C13: Chi phí bán hàng Quý 1 năm 2026 | D13: 0
C14: Chi phí tài chính Quý 1 năm 2026 | D14: =[5]Sheet24!J41
C15: Chi phí quản lý doanh nghiệp Quý 1 năm 2026 | D15: =[5]Sheet24!P42
C16: Chi phí khác | D16: =[5]Sheet24!M48
B17: 3 | C17: Chi phí không được khấu trừ thuế TNDN Quý 1 năm 2026 | D17: =SUM(D18:D20)
C18: Chi thù lao chủ tịch + kiểm soát viên | D18: =15000000
C19: Chi phí marketing khuyến mại giữ lại cho chi nhánh | D19: 0
C20: Chi phí khác | D20: =[5]Sheet24!F48
B21: 4 | C21: Chi phí tính thuế TNDN Quý 1 năm 2026 | D21: =D11-D17
B22: 5 | C22: Thu nhập tính thuế thuế Quý 1 năm 2026 | D22: =D7-D21
B23: 6 | C23: Thuế TNDN Quý 1 năm 2026 | D23: =ROUND(D22*0.2,0)
B24: 7 | C24: Thuế TNDN quý 1.2024
B25: 8 | C25: Thuế TNDN Quý 2.2024
B26: 9 | C26: Thuế TNDN quý 3.2024
B27: 10 | C27: Thuế TNDN quý 4.2024 | D27: =D23-D24-D25-D26
B28: 7 | C28: Lợi nhuận trước thuế | D28: =D7-D11
B29: 8 | C29: Lợi nhuận sau thuế Quý 1 năm 2026 | D29: =D28-D23
B31: Lập bảng Kiểm soát Tổng giám đốc
